Traceback (most recent call last):
  File "/usr/local/bin/certbot", line 11, in <module>
    load_entry_point('certbot==0.9.0', 'console_scripts', 'certbot')()
  File "/usr/local/Cellar/certbot/0.9.0/libexec/lib/python2.7/site-packages/certbot/main.py", line 741, in main
    setup_logging(config, _cli_log_handler, logfile='letsencrypt.log')
  File "/usr/local/Cellar/certbot/0.9.0/libexec/lib/python2.7/site-packages/certbot/main.py", line 634, in setup_logging
    config, logfile=logfile, fmt=file_fmt)
  File "/usr/local/Cellar/certbot/0.9.0/libexec/lib/python2.7/site-packages/certbot/main.py", line 604, in setup_log_file_handler
    raise errors.Error(_PERM_ERR_FMT.format(error))
Error: The following error was encountered:
[Errno 13] Permission denied: '/var/log/letsencrypt/letsencrypt.log'
If running as non-root, set --config-dir, --logs-dir, and --work-dir to writeable paths.
